import logging

from django.conf import settings

from django.core.management import call_command
from django.db.models import loading

from django.http import HttpRequest
from django.test.client import Client

from nose.tools import assert_equal, with_setup, assert_false, eq_, ok_
from nose.plugins.attrib import attr

from django.template.defaultfilters import slugify

from django.contrib.auth.models import User

from . import BadgerTestCase

import badger

from badger.models import (Badge, Award, Progress,
        BadgeAwardNotAllowedException,
        BadgeAlreadyAwardedException)

from badger_test.models import GuestbookEntry


class BadgerBadgeTest(BadgerTestCase):

    def setUp(self):
        self.user_1 = self._get_user(username="user_1",
                email="user_1@example.com", password="user_1_pass")

    def tearDown(self):
        Award.objects.all().delete()
        Badge.objects.all().delete()

    def test_get_badge(self):
        """Can create a badge"""
        badge = self._get_badge()

        eq_(slugify(badge.title), badge.slug)
        ok_(badge.created is not None)
        ok_(badge.modified is not None)
        eq_(badge.created.year, badge.modified.year)
        eq_(badge.created.month, badge.modified.month)
        eq_(badge.created.day, badge.modified.day)

    def test_award_badge(self):
        """Can award a badge to a user"""
        badge = self._get_badge()
        user = self._get_user()

        ok_(not badge.is_awarded_to(user))
        badge.award_to(awardee=user, awarder=badge.creator)
        ok_(badge.is_awarded_to(user))

    def test_award_unique_duplication(self):
        """Only one award for a unique badge can be created"""
        user = self._get_user()
        b = Badge.objects.create(slug='one-and-only', title='One and Only',
                unique=True, creator=user)
        a = Award.objects.create(badge=b, user=user)

        # award_to should not trigger the exception
        b.award_to(user)

        try:
            a = Award.objects.create(badge=b, user=user)
            ok_(False, 'BadgeAlreadyAwardedException should have been raised')
        except BadgeAlreadyAwardedException, e:
            # But, directly creating another award should trigger the exception
            pass

        eq_(1, Award.objects.filter(badge=b, user=user).count())

    @attr('current')
    def test_progress_badge_already_awarded(self):
        """New progress toward an awarded unique badge cannot be recorded"""
        user = self._get_user()
        b = Badge.objects.create(slug='one-and-only', title='One and Only',
                unique=True, creator=user)

        p = b.progress_for(user)
        p.update_percent(100)

        try:
            p = Progress.objects.create(badge=b, user=user)
            ok_(False, 'BadgeAlreadyAwardedException should have been raised')
        except BadgeAlreadyAwardedException, e:
            pass

        # None, because award deletes progress.
        eq_(0, Progress.objects.filter(badge=b, user=user).count())

    def _get_user(self, username="tester", email="tester@example.com",
            password="trustno1"):
        (user, created) = User.objects.get_or_create(username=username,
                defaults=dict(email=email))
        if created:
            user.set_password(password)
            user.save()
        return user

    def _get_badge(self, title="Test Badge",
            description="This is a test badge", creator=None):
        creator = creator or self.user_1
        (badge, created) = Badge.objects.get_or_create(title=title,
                defaults=dict(description=description, creator=creator))
        return badge
